Traceback (most recent call last):
  File "/home/codespace/.local/lib/python3.12/site-packages/jupyter_core/utils/__init__.py", line 154, in wrapped
    asyncio.get_running_loop()
RuntimeError: no running event loop

During handling of the above exception, another exception occurred:

Traceback (most recent call last):
  File "/usr/local/python/3.12.1/lib/python3.12/site-packages/jupyter_cache/executors/utils.py", line 58, in single_nb_execution
    executenb(
  File "/home/codespace/.local/lib/python3.12/site-packages/nbclient/client.py", line 1319, in execute
    return NotebookClient(nb=nb, resources=resources, km=km, **kwargs).execute()
           ^^^^^^^^^^^^^^^^^^^^^^^^^^^^^^^^^^^^^^^^^^^^^^^^^^^^^^^^^^^^^^^^^^^^^
  File "/home/codespace/.local/lib/python3.12/site-packages/jupyter_core/utils/__init__.py", line 158, in wrapped
    return loop.run_until_complete(inner)
           ^^^^^^^^^^^^^^^^^^^^^^^^^^^^^^
  File "/usr/local/python/3.12.1/lib/python3.12/asyncio/base_events.py", line 684, in run_until_complete
    return future.result()
           ^^^^^^^^^^^^^^^
  File "/home/codespace/.local/lib/python3.12/site-packages/nbclient/client.py", line 709, in async_execute
    await self.async_execute_cell(
  File "/home/codespace/.local/lib/python3.12/site-packages/nbclient/client.py", line 1062, in async_execute_cell
    await self._check_raise_for_error(cell, cell_index, exec_reply)
  File "/home/codespace/.local/lib/python3.12/site-packages/nbclient/client.py", line 918, in _check_raise_for_error
    raise CellExecutionError.from_cell_and_msg(cell, exec_reply_content)
nbclient.exceptions.CellExecutionError: An error occurred while executing the following cell:
------------------
%pip install pymysql
import pymysql

# Koneksi ke MySQL
mysql_conn = pymysql.connect(
    host="mysql-3c768195-aqbilbaraka.d.aivencloud.com",
    user="avnadmin",
    password="AVNS_WV9i6KvYoQZ3s6FclWP",
    database="defaultdb",
    port=16932,
    ssl={"ssl": {}}
)
mysql_cur = mysql_conn.cursor()

# Eksekusi query untuk mengambil data dari MySQL
query_mysql = "SELECT * FROM irismysql"
mysql_cur.execute(query_mysql)
data_mysql = mysql_cur.fetchall()

# Menampilkan data dari MySQL
print("DATA SQL")
for row in data_mysql:
    print(row)

# Tutup kursor dan koneksi
mysql_cur.close()
mysql_conn.close()
------------------

----- stdout -----
Collecting pymysql
----- stdout -----
  Downloading pymysql-1.1.2-py3-none-any.whl.metadata (4.3 kB)
Downloading pymysql-1.1.2-py3-none-any.whl (45 kB)
----- stdout -----
Installing collected packages: pymysql
----- stdout -----
Successfully installed pymysql-1.1.2

[1m[[0m[34;49mnotice[0m[1;39;49m][0m[39;49m A new release of pip is available: [0m[31;49m25.1.1[0m[39;49m -> [0m[32;49m25.2[0m
[1m[[0m[34;49mnotice[0m[1;39;49m][0m[39;49m To update, run: [0m[32;49mpython3 -m pip install --upgrade pip[0m
----- stdout -----
Note: you may need to restart the kernel to use updated packages.
------------------

[31m---------------------------------------------------------------------------[39m
[31mgaierror[39m                                  Traceback (most recent call last)
[36mFile [39m[32m/usr/local/python/3.12.1/lib/python3.12/site-packages/pymysql/connections.py:661[39m, in [36mConnection.connect[39m[34m(self, sock)[39m
[32m    660[39m [38;5;28;01mtry[39;00m:
[32m--> [39m[32m661[39m     sock = [43msocket[49m[43m.[49m[43mcreate_connection[49m[43m([49m
[32m    662[39m [43m        [49m[43m([49m[38;5;28;43mself[39;49m[43m.[49m[43mhost[49m[43m,[49m[43m [49m[38;5;28;43mself[39;49m[43m.[49m[43mport[49m[43m)[49m[43m,[49m[43m [49m[38;5;28;43mself[39;49m[43m.[49m[43mconnect_timeout[49m[43m,[49m[43m [49m[43m*[49m[43m*[49m[43mkwargs[49m
[32m    663[39m [43m    [49m[43m)[49m
[32m    664[39m     [38;5;28;01mbreak[39;00m

[36mFile [39m[32m/usr/local/python/3.12.1/lib/python3.12/socket.py:828[39m, in [36mcreate_connection[39m[34m(address, timeout, source_address, all_errors)[39m
[32m    827[39m exceptions = []
[32m--> [39m[32m828[39m [38;5;28;01mfor[39;00m res [38;5;129;01min[39;00m [43mgetaddrinfo[49m[43m([49m[43mhost[49m[43m,[49m[43m [49m[43mport[49m[43m,[49m[43m [49m[32;43m0[39;49m[43m,[49m[43m [49m[43mSOCK_STREAM[49m[43m)[49m:
[32m    829[39m     af, socktype, proto, canonname, sa = res

[36mFile [39m[32m/usr/local/python/3.12.1/lib/python3.12/socket.py:963[39m, in [36mgetaddrinfo[39m[34m(host, port, family, type, proto, flags)[39m
[32m    962[39m addrlist = []
[32m--> [39m[32m963[39m [38;5;28;01mfor[39;00m res [38;5;129;01min[39;00m [43m_socket[49m[43m.[49m[43mgetaddrinfo[49m[43m([49m[43mhost[49m[43m,[49m[43m [49m[43mport[49m[43m,[49m[43m [49m[43mfamily[49m[43m,[49m[43m [49m[38;5;28;43mtype[39;49m[43m,[49m[43m [49m[43mproto[49m[43m,[49m[43m [49m[43mflags[49m[43m)[49m:
[32m    964[39m     af, socktype, proto, canonname, sa = res

[31mgaierror[39m: [Errno -2] Name or service not known

During handling of the above exception, another exception occurred:

[31mOperationalError[39m                          Traceback (most recent call last)
[36mCell[39m[36m [39m[32mIn[1][39m[32m, line 5[39m
[32m      2[39m [38;5;28;01mimport[39;00m[38;5;250m [39m[34;01mpymysql[39;00m
[32m      4[39m [38;5;66;03m# Koneksi ke MySQL[39;00m
[32m----> [39m[32m5[39m mysql_conn = [43mpymysql[49m[43m.[49m[43mconnect[49m[43m([49m
[32m      6[39m [43m    [49m[43mhost[49m[43m=[49m[33;43m"[39;49m[33;43mmysql-3c768195-aqbilbaraka.d.aivencloud.com[39;49m[33;43m"[39;49m[43m,[49m
[32m      7[39m [43m    [49m[43muser[49m[43m=[49m[33;43m"[39;49m[33;43mavnadmin[39;49m[33;43m"[39;49m[43m,[49m
[32m      8[39m [43m    [49m[43mpassword[49m[43m=[49m[33;43m"[39;49m[33;43mAVNS_WV9i6KvYoQZ3s6FclWP[39;49m[33;43m"[39;49m[43m,[49m
[32m      9[39m [43m    [49m[43mdatabase[49m[43m=[49m[33;43m"[39;49m[33;43mdefaultdb[39;49m[33;43m"[39;49m[43m,[49m
[32m     10[39m [43m    [49m[43mport[49m[43m=[49m[32;43m16932[39;49m[43m,[49m
[32m     11[39m [43m    [49m[43mssl[49m[43m=[49m[43m{[49m[33;43m"[39;49m[33;43mssl[39;49m[33;43m"[39;49m[43m:[49m[43m [49m[43m{[49m[43m}[49m[43m}[49m
[32m     12[39m [43m)[49m
[32m     13[39m mysql_cur = mysql_conn.cursor()
[32m     15[39m [38;5;66;03m# Eksekusi query untuk mengambil data dari MySQL[39;00m

[36mFile [39m[32m/usr/local/python/3.12.1/lib/python3.12/site-packages/pymysql/connections.py:365[39m, in [36mConnection.__init__[39m[34m(self, user, password, host, database, unix_socket, port, charset, collation, sql_mode, read_default_file, conv, use_unicode, client_flag, cursorclass, init_command, connect_timeout, read_default_group, autocommit, local_infile, max_allowed_packet, defer_connect, auth_plugin_map, read_timeout, write_timeout, bind_address, binary_prefix, program_name, server_public_key, ssl, ssl_ca, ssl_cert, ssl_disabled, ssl_key, ssl_key_password, ssl_verify_cert, ssl_verify_identity, compress, named_pipe, passwd, db)[39m
[32m    363[39m     [38;5;28mself[39m._sock = [38;5;28;01mNone[39;00m
[32m    364[39m [38;5;28;01melse[39;00m:
[32m--> [39m[32m365[39m     [38;5;28;43mself[39;49m[43m.[49m[43mconnect[49m[43m([49m[43m)[49m

[36mFile [39m[32m/usr/local/python/3.12.1/lib/python3.12/site-packages/pymysql/connections.py:723[39m, in [36mConnection.connect[39m[34m(self, sock)[39m
[32m    721[39m     [38;5;28;01mif[39;00m DEBUG:
[32m    722[39m         [38;5;28mprint[39m(exc.traceback)
[32m--> [39m[32m723[39m     [38;5;28;01mraise[39;00m exc
[32m    725[39m [38;5;66;03m# If e is neither DatabaseError or IOError, It's a bug.[39;00m
[32m    726[39m [38;5;66;03m# But raising AssertionError hides original error.[39;00m
[32m    727[39m [38;5;66;03m# So just reraise it.[39;00m
[32m    728[39m [38;5;28;01mraise[39;00m

[31mOperationalError[39m: (2003, "Can't connect to MySQL server on 'mysql-3c768195-aqbilbaraka.d.aivencloud.com' ([Errno -2] Name or service not known)")

